<?xml version="1.0"?>
<!--
robot.urdf
Differential drive parking robot with bigger rear caster sphere
-->

<robot name="parking_bot">

  <!-- =========================
       LINKS
       ========================= -->

  <!-- Base chassis -->
  <link name="base_link">
    <visual>
      <origin xyz="0 0 0" rpy="0 0 0"/>
      <geometry>
        <box size="0.4 0.3 0.1"/>
      </geometry>
      <material name="blue">
        <color rgba="0.05 0.2 0.85 1"/>
      </material>
    </visual>

    <collision>
      <origin xyz="0 0 0" rpy="0 0 0"/>
      <geometry>
        <box size="0.4 0.3 0.1"/>
      </geometry>
    </collision>

    <inertial>
      <mass value="5.0"/>
      <inertia ixx="0.0458" ixy="0.0" ixz="0.0"
               iyy="0.0792" iyz="0.0"
               izz="0.1042"/>
    </inertial>
  </link>

  <!-- Left wheel -->
  <link name="left_wheel">
    <visual>
      <geometry>
        <cylinder radius="0.1" length="0.05"/>
      </geometry>
      <material name="dark_grey">
        <color rgba="0.15 0.15 0.15 1"/>
      </material>
    </visual>

    <collision>
      <geometry>
        <cylinder radius="0.1" length="0.05"/>
      </geometry>
    </collision>

    <inertial>
      <mass value="1.0"/>
      <inertia ixx="0.00208" ixy="0.0" ixz="0.0"
               iyy="0.00208" iyz="0.0"
               izz="0.005"/>
    </inertial>
  </link>

  <!-- Right wheel -->
  <link name="right_wheel">
    <visual>
      <geometry>
        <cylinder radius="0.1" length="0.05"/>
      </geometry>
      <material name="dark_grey">
        <color rgba="0.15 0.15 0.15 1"/>
      </material>
    </visual>

    <collision>
      <geometry>
        <cylinder radius="0.1" length="0.05"/>
      </geometry>
    </collision>

    <inertial>
      <mass value="1.0"/>
      <inertia ixx="0.00208" ixy="0.0" ixz="0.0"
               iyy="0.00208" iyz="0.0"
               izz="0.005"/>
    </inertial>
  </link>

  <!-- Rear caster sphere (UPDATED BIGGER) -->
  <link name="caster_link">
    <visual>
      <geometry>
        <sphere radius="0.07"/>
      </geometry>
      <material name="silver">
        <color rgba="0.7 0.7 0.7 1"/>
      </material>
    </visual>

    <collision>
      <geometry>
        <sphere radius="0.07"/>
      </geometry>
    </collision>

    <inertial>
      <mass value="1.0"/>
      <inertia ixx="0.001" ixy="0.0" ixz="0.0"
               iyy="0.001" iyz="0.0"
               izz="0.001"/>
    </inertial>
  </link>

  <!-- LiDAR -->
  <link name="lidar_link">
    <visual>
      <geometry>
        <cylinder radius="0.04" length="0.05"/>
      </geometry>
      <material name="red">
        <color rgba="0.9 0.1 0.1 1"/>
      </material>
    </visual>

    <collision>
      <geometry>
        <cylinder radius="0.04" length="0.05"/>
      </geometry>
    </collision>

    <inertial>
      <mass value="0.2"/>
      <inertia ixx="0.0001" ixy="0.0" ixz="0.0"
               iyy="0.0001" iyz="0.0"
               izz="0.0002"/>
    </inertial>
  </link>

  <!-- =========================
       JOINTS
       ========================= -->

  <!-- Left wheel joint -->
  <joint name="left_wheel_joint" type="continuous">
    <parent link="base_link"/>
    <child link="left_wheel"/>
    <origin xyz="0.0 0.175 -0.05" rpy="-1.5708 0 0"/>
    <axis xyz="0 0 1"/>
    <dynamics damping="0.1" friction="0.1"/>
  </joint>

  <!-- Right wheel joint -->
  <joint name="right_wheel_joint" type="continuous">
    <parent link="base_link"/>
    <child link="right_wheel"/>
    <origin xyz="0.0 -0.175 -0.05" rpy="-1.5708 0 0"/>
    <axis xyz="0 0 1"/>
    <dynamics damping="0.1" friction="0.1"/>
  </joint>

  <!-- Rear caster joint (UPDATED LOWERED) -->
  <joint name="caster_joint" type="fixed">
    <parent link="base_link"/>
    <child link="caster_link"/>
    <origin xyz="-0.16 0 -0.10" rpy="0 0 0"/>
  </joint>

  <!-- LiDAR joint -->
  <joint name="lidar_joint" type="fixed">
    <parent link="base_link"/>
    <child link="lidar_link"/>
    <origin xyz="0.20 -0.1 0.1" rpy="0 0 0"/>
  </joint>

  <!-- =========================
       GAZEBO PLUGINS
       ========================= -->

  <!-- Diff drive plugin -->
  <gazebo>
    <plugin name="diff_drive_controller" filename="libgazebo_ros_diff_drive.so">

      <ros>
        <namespace>/</namespace>
        <remapping>cmd_vel:=cmd_vel</remapping>
        <remapping>odom:=odom</remapping>
      </ros>

      <left_joint>left_wheel_joint</left_joint>
      <right_joint>right_wheel_joint</right_joint>

      <wheel_separation>0.35</wheel_separation>
      <wheel_diameter>0.20</wheel_diameter>

      <max_wheel_torque>20</max_wheel_torque>
      <max_wheel_acceleration>1.0</max_wheel_acceleration>

      <command_topic>cmd_vel</command_topic>
      <odometry_topic>odom</odometry_topic>
      <odometry_frame>odom</odometry_frame>
      <robot_base_frame>base_link</robot_base_frame>

      <publish_odom>true</publish_odom>
      <publish_odom_tf>true</publish_odom_tf>
      <publish_wheel_tf>true</publish_wheel_tf>
      <publish_wheel_joint_state>true</publish_wheel_joint_state>

      <update_rate>50</update_rate>

    </plugin>
  </gazebo>

  <!-- LiDAR sensor -->
  <gazebo reference="lidar_link">
    <sensor name="lidar_sensor" type="ray">
      <pose>0 0 0 0 0 0</pose>
      <always_on>true</always_on>
      <visualize>true</visualize>
      <update_rate>20</update_rate>

      <ray>
        <scan>
          <horizontal>
            <samples>360</samples>
            <resolution>1</resolution>
            <min_angle>-3.14159265</min_angle>
            <max_angle>3.14159265</max_angle>
          </horizontal>
        </scan>

        <range>
          <min>0.12</min>
          <max>6.0</max>
          <resolution>0.01</resolution>
        </range>

        <noise>
          <type>gaussian</type>
          <mean>0.0</mean>
          <stddev>0.01</stddev>
        </noise>
      </ray>

      <plugin name="lidar_plugin" filename="libgazebo_ros_ray_sensor.so">
        <ros>
          <remapping>~/out:=scan</remapping>
        </ros>
        <output_type>sensor_msgs/LaserScan</output_type>
        <frame_name>lidar_link</frame_name>
      </plugin>
    </sensor>
  </gazebo>

  <!-- Gazebo colors -->
  <gazebo reference="base_link">
    <material>Gazebo/Blue</material>
  </gazebo>

  <gazebo reference="left_wheel">
    <material>Gazebo/DarkGrey</material>
  </gazebo>

  <gazebo reference="right_wheel">
    <material>Gazebo/DarkGrey</material>
  </gazebo>

  <gazebo reference="caster_link">
    <material>Gazebo/Grey</material>
    <mu1>0.0</mu1>
    <mu2>0.0</mu2>
  </gazebo>

  <gazebo reference="lidar_link">
    <material>Gazebo/Red</material>
  </gazebo>

</robot>
